[2023-12-21T08:43:27.402+0000] {taskinstance.py:1159} INFO - Dependencies all met for dep_context=non-requeueable deps ti=<TaskInstance: 12_21_fx_mkt_data.first_attempt scheduled__2023-12-19T00:00:00+00:00 [queued]>
[2023-12-21T08:43:27.436+0000] {taskinstance.py:1159} INFO - Dependencies all met for dep_context=requeueable deps ti=<TaskInstance: 12_21_fx_mkt_data.first_attempt scheduled__2023-12-19T00:00:00+00:00 [queued]>
[2023-12-21T08:43:27.437+0000] {taskinstance.py:1361} INFO - Starting attempt 1 of 6
[2023-12-21T08:43:27.519+0000] {taskinstance.py:1382} INFO - Executing <Task(PythonOperator): first_attempt> on 2023-12-19 00:00:00+00:00
[2023-12-21T08:43:27.721+0000] {standard_task_runner.py:57} INFO - Started process 565 to run task
[2023-12-21T08:43:27.801+0000] {standard_task_runner.py:84} INFO - Running: ['airflow', 'tasks', 'run', '12_21_fx_mkt_data', 'first_attempt', 'scheduled__2023-12-19T00:00:00+00:00', '--job-id', '32', '--raw', '--subdir', 'DAGS_FOLDER/get_fx_mkt_data.py', '--cfg-path', '/tmp/tmpfvlz21qu']
[2023-12-21T08:43:27.812+0000] {standard_task_runner.py:85} INFO - Job 32: Subtask first_attempt
[2023-12-21T08:43:28.372+0000] {task_command.py:416} INFO - Running <TaskInstance: 12_21_fx_mkt_data.first_attempt scheduled__2023-12-19T00:00:00+00:00 [running]> on host a265892d508c
[2023-12-21T08:43:29.163+0000] {taskinstance.py:1662} INFO - Exporting env vars: AIRFLOW_CTX_DAG_OWNER='airflow' AIRFLOW_CTX_DAG_ID='12_21_fx_mkt_data' AIRFLOW_CTX_TASK_ID='first_attempt' AIRFLOW_CTX_EXECUTION_DATE='2023-12-19T00:00:00+00:00' AIRFLOW_CTX_TRY_NUMBER='1' AIRFLOW_CTX_DAG_RUN_ID='scheduled__2023-12-19T00:00:00+00:00'
[2023-12-21T08:43:29.166+0000] {oandapyV20.py:207} INFO - setting up API-client for environment practice
[2023-12-21T08:43:35.597+0000] {taskinstance.py:1937} ERROR - Task failed with exception
Traceback (most recent call last):
  File "/home/airflow/.local/lib/python3.8/site-packages/airflow/operators/python.py", line 192, in execute
    return_value = self.execute_callable()
  File "/home/airflow/.local/lib/python3.8/site-packages/airflow/operators/python.py", line 209, in execute_callable
    return self.python_callable(*self.op_args, **self.op_kwargs)
  File "/opt/airflow/app/sal/etl/main.py", line 40, in main
    tickers = s3_data_service.read_excel("tickers.xlsx", sheet_name="daily").tolist()
  File "/home/airflow/.local/lib/python3.8/site-packages/pandas/core/generic.py", line 5989, in __getattr__
    return object.__getattribute__(self, name)
AttributeError: 'DataFrame' object has no attribute 'tolist'
[2023-12-21T08:43:35.713+0000] {taskinstance.py:1400} INFO - Marking task as UP_FOR_RETRY. dag_id=12_21_fx_mkt_data, task_id=first_attempt, execution_date=20231219T000000, start_date=20231221T084327, end_date=20231221T084335
[2023-12-21T08:43:35.831+0000] {standard_task_runner.py:104} ERROR - Failed to execute job 32 for task first_attempt ('DataFrame' object has no attribute 'tolist'; 565)
[2023-12-21T08:43:35.879+0000] {local_task_job_runner.py:228} INFO - Task exited with return code 1
[2023-12-21T08:43:35.987+0000] {taskinstance.py:2778} INFO - 0 downstream tasks scheduled from follow-on schedule check
