[2023-12-21T09:40:06.399+0000] {taskinstance.py:1159} INFO - Dependencies all met for dep_context=non-requeueable deps ti=<TaskInstance: 12_21_fx_mkt_data.first_attempt manual__2023-12-21T09:40:02.711409+00:00 [queued]>
[2023-12-21T09:40:06.435+0000] {taskinstance.py:1159} INFO - Dependencies all met for dep_context=requeueable deps ti=<TaskInstance: 12_21_fx_mkt_data.first_attempt manual__2023-12-21T09:40:02.711409+00:00 [queued]>
[2023-12-21T09:40:06.436+0000] {taskinstance.py:1361} INFO - Starting attempt 1 of 6
[2023-12-21T09:40:06.494+0000] {taskinstance.py:1382} INFO - Executing <Task(PythonOperator): first_attempt> on 2023-12-21 09:40:02.711409+00:00
[2023-12-21T09:40:06.511+0000] {standard_task_runner.py:57} INFO - Started process 1376 to run task
[2023-12-21T09:40:06.519+0000] {standard_task_runner.py:84} INFO - Running: ['airflow', 'tasks', 'run', '12_21_fx_mkt_data', 'first_attempt', 'manual__2023-12-21T09:40:02.711409+00:00', '--job-id', '66', '--raw', '--subdir', 'DAGS_FOLDER/get_fx_mkt_data.py', '--cfg-path', '/tmp/tmp7mkliwl4']
[2023-12-21T09:40:06.526+0000] {standard_task_runner.py:85} INFO - Job 66: Subtask first_attempt
[2023-12-21T09:40:06.755+0000] {task_command.py:416} INFO - Running <TaskInstance: 12_21_fx_mkt_data.first_attempt manual__2023-12-21T09:40:02.711409+00:00 [running]> on host a265892d508c
[2023-12-21T09:40:07.139+0000] {taskinstance.py:1662} INFO - Exporting env vars: AIRFLOW_CTX_DAG_OWNER='airflow' AIRFLOW_CTX_DAG_ID='12_21_fx_mkt_data' AIRFLOW_CTX_TASK_ID='first_attempt' AIRFLOW_CTX_EXECUTION_DATE='2023-12-21T09:40:02.711409+00:00' AIRFLOW_CTX_TRY_NUMBER='1' AIRFLOW_CTX_DAG_RUN_ID='manual__2023-12-21T09:40:02.711409+00:00'
[2023-12-21T09:40:07.143+0000] {oandapyV20.py:207} INFO - setting up API-client for environment practice
[2023-12-21T09:40:08.182+0000] {taskinstance.py:1937} ERROR - Task failed with exception
Traceback (most recent call last):
  File "/home/airflow/.local/lib/python3.8/site-packages/airflow/operators/python.py", line 192, in execute
    return_value = self.execute_callable()
  File "/home/airflow/.local/lib/python3.8/site-packages/airflow/operators/python.py", line 209, in execute_callable
    return self.python_callable(*self.op_args, **self.op_kwargs)
  File "/opt/airflow/app/sal/etl/main.py", line 61, in main
    data = fx_data_service.fetch_historical_data(instrument=instrument, start_date=_from, granularity=granularity)
TypeError: fetch_historical_data() missing 1 required positional argument: 'end_date'
[2023-12-21T09:40:08.242+0000] {taskinstance.py:1400} INFO - Marking task as UP_FOR_RETRY. dag_id=12_21_fx_mkt_data, task_id=first_attempt, execution_date=20231221T094002, start_date=20231221T094006, end_date=20231221T094008
[2023-12-21T09:40:08.291+0000] {standard_task_runner.py:104} ERROR - Failed to execute job 66 for task first_attempt (fetch_historical_data() missing 1 required positional argument: 'end_date'; 1376)
[2023-12-21T09:40:08.337+0000] {local_task_job_runner.py:228} INFO - Task exited with return code 1
[2023-12-21T09:40:08.423+0000] {taskinstance.py:2778} INFO - 0 downstream tasks scheduled from follow-on schedule check
