[2023-12-20T16:15:45.117+0000] {taskinstance.py:1159} INFO - Dependencies all met for dep_context=non-requeueable deps ti=<TaskInstance: 12_14_download_fx_mkt_data.first_attempt manual__2023-12-20T16:15:41.916180+00:00 [queued]>
[2023-12-20T16:15:45.154+0000] {taskinstance.py:1159} INFO - Dependencies all met for dep_context=requeueable deps ti=<TaskInstance: 12_14_download_fx_mkt_data.first_attempt manual__2023-12-20T16:15:41.916180+00:00 [queued]>
[2023-12-20T16:15:45.156+0000] {taskinstance.py:1361} INFO - Starting attempt 1 of 6
[2023-12-20T16:15:45.208+0000] {taskinstance.py:1382} INFO - Executing <Task(PythonOperator): first_attempt> on 2023-12-20 16:15:41.916180+00:00
[2023-12-20T16:15:45.222+0000] {standard_task_runner.py:57} INFO - Started process 6610 to run task
[2023-12-20T16:15:45.230+0000] {standard_task_runner.py:84} INFO - Running: ['airflow', 'tasks', 'run', '12_14_download_fx_mkt_data', 'first_attempt', 'manual__2023-12-20T16:15:41.916180+00:00', '--job-id', '15', '--raw', '--subdir', 'DAGS_FOLDER/get_fx_mkt_data.py', '--cfg-path', '/tmp/tmp80o1vk92']
[2023-12-20T16:15:45.233+0000] {standard_task_runner.py:85} INFO - Job 15: Subtask first_attempt
[2023-12-20T16:15:45.485+0000] {task_command.py:416} INFO - Running <TaskInstance: 12_14_download_fx_mkt_data.first_attempt manual__2023-12-20T16:15:41.916180+00:00 [running]> on host 39ff41744a35
[2023-12-20T16:15:45.898+0000] {taskinstance.py:1662} INFO - Exporting env vars: AIRFLOW_CTX_DAG_OWNER='airflow' AIRFLOW_CTX_DAG_ID='12_14_download_fx_mkt_data' AIRFLOW_CTX_TASK_ID='first_attempt' AIRFLOW_CTX_EXECUTION_DATE='2023-12-20T16:15:41.916180+00:00' AIRFLOW_CTX_TRY_NUMBER='1' AIRFLOW_CTX_DAG_RUN_ID='manual__2023-12-20T16:15:41.916180+00:00'
[2023-12-20T16:15:45.901+0000] {taskinstance.py:1937} ERROR - Task failed with exception
Traceback (most recent call last):
  File "/home/airflow/.local/lib/python3.8/site-packages/airflow/operators/python.py", line 192, in execute
    return_value = self.execute_callable()
  File "/home/airflow/.local/lib/python3.8/site-packages/airflow/operators/python.py", line 209, in execute_callable
    return self.python_callable(*self.op_args, **self.op_kwargs)
  File "/opt/airflow/app/sal/etl/main.py", line 31, in main
    s3_data_service = S3DataService(
  File "/opt/airflow/app/sal/services/boto/data_service.py", line 4, in __init__
    self.client = boto3.client(
NameError: name 'boto3' is not defined
[2023-12-20T16:15:45.959+0000] {taskinstance.py:1400} INFO - Marking task as UP_FOR_RETRY. dag_id=12_14_download_fx_mkt_data, task_id=first_attempt, execution_date=20231220T161541, start_date=20231220T161545, end_date=20231220T161545
[2023-12-20T16:15:46.008+0000] {standard_task_runner.py:104} ERROR - Failed to execute job 15 for task first_attempt (name 'boto3' is not defined; 6610)
[2023-12-20T16:15:46.044+0000] {local_task_job_runner.py:228} INFO - Task exited with return code 1
[2023-12-20T16:15:46.129+0000] {taskinstance.py:2778} INFO - 0 downstream tasks scheduled from follow-on schedule check
